Workbook

Sheet Dashboard
P1: helper
B2: APPLICATION COMMAND CENTRE | P2: =_xlfn.MINIFS(Tracker!$H$5:$H$104,Tracker!$H$5:$H$104,">="&TODAY(),Tracker!$J$5:$J$104,"<>Yes") -> 46311
B3: Live metrics — updates automatically from the Tracker sheet
B5: TOTAL OPPORTUNITIES | E5: APPLICATIONS SUBMITTED | H5: DEADLINES IN 21 DAYS | K5: NEXT DEADLINE
B6: =COUNTA(Tracker!$B$5:$B$104) -> 30 | E6: =COUNTIF(Tracker!$J$5:$J$104,"Yes") -> 1 | H6: =COUNTIFS(Tracker!$H$5:$H$104,">="&TODAY(),Tracker!$H$5:$H$104,"<="&TODAY()+21,Tracker!$J$5:$J$104,"<>Yes") -> 4 | K6: =IF(OR(P2=0,P2=""),"—",P2) -> 46311
B7: employers / roles tracked | E7: marked Applied = Yes | H7: not yet applied | K7: nearest open date
B9: ONLINE ASSESSMENTS | E9: INTERVIEWS | H9: ASSESSMENT CENTRES | K9: OFFERS
B10: =SUMPRODUCT((Tracker!$M$5:$M$104<>"")*(Tracker!$M$5:$M$104<>"Not Invited")) -> 0 | E10: =SUMPRODUCT((Tracker!$O$5:$O$104<>"")*(Tracker!$O$5:$O$104<>"Not Invited")) -> 0 | H10: =SUMPRODUCT((Tracker!$Q$5:$Q$104<>"")*(Tracker!$Q$5:$Q$104<>"Not Invited")) -> 0 | K10: =COUNTIF(Tracker!$S$5:$S$104,"Offer Received")+COUNTIF(Tracker!$S$5:$S$104,"Accepted") -> 0
B11: invited or beyond | E11: invited or beyond | H11: invited or beyond | K11: received or accepted
B13: APPLICATION FUNNEL
B14: Stage | E14: Count | F14: % of Applied
B15: Applied | E15: =COUNTIF(Tracker!$J$5:$J$104,"Yes") -> 1 | F15: =IF($E$15=0,0,E15/$E$15) -> 1
B16: Online Assessment | E16: =SUMPRODUCT((Tracker!$M$5:$M$104<>"")*(Tracker!$M$5:$M$104<>"Not Invited")) -> 0 | F16: =IF($E$15=0,0,E16/$E$15) -> 0
B17: Interview | E17: =SUMPRODUCT((Tracker!$O$5:$O$104<>"")*(Tracker!$O$5:$O$104<>"Not Invited")) -> 0 | F17: =IF($E$15=0,0,E17/$E$15) -> 0
B18: Assessment Centre | E18: =SUMPRODUCT((Tracker!$Q$5:$Q$104<>"")*(Tracker!$Q$5:$Q$104<>"Not Invited")) -> 0 | F18: =IF($E$15=0,0,E18/$E$15) -> 0
B19: Offer | E19: =COUNTIF(Tracker!$S$5:$S$104,"Offer Received")+COUNTIF(Tracker!$S$5:$S$104,"Accepted") -> 0 | F19: =IF($E$15=0,0,E19/$E$15) -> 0
B22: SPONSORSHIP OUTLOOK | H22: HOW TO USE
B23: Outlook | E23: Roles | F23: Applied | H23: ▸ Tracker is the single source of truth — everything here recalculates.
B24: High Potential | E24: =COUNTIF(Tracker!$F$5:$F$104,B24) -> 10 | F24: =COUNTIFS(Tracker!$F$5:$F$104,B24,Tracker!$J$5:$J$104,"Yes") -> 0 | H24: ▸ Dropdowns: Sponsorship, Priority, Applied?, Status, assessment stages, Offer.
B25: Check per role | E25: =COUNTIF(Tracker!$F$5:$F$104,B25) -> 10 | F25: =COUNTIFS(Tracker!$F$5:$F$104,B25,Tracker!$J$5:$J$104,"Yes") -> 0 | H25: ▸ Date cells (Deadline, Date Applied, stage dates) accept only valid dates.
B26: Selective | E26: =COUNTIF(Tracker!$F$5:$F$104,B26) -> 3 | F26: =COUNTIFS(Tracker!$F$5:$F$104,B26,Tracker!$J$5:$J$104,"Yes") -> 0 | H26: ▸ Press Ctrl + ; to insert today's date; click a date cell for the prompt.
B27: Role Dependent | E27: =COUNTIF(Tracker!$F$5:$F$104,B27) -> 1 | F27: =COUNTIFS(Tracker!$F$5:$F$104,B27,Tracker!$J$5:$J$104,"Yes") -> 0 | H27: ▸ Days Left turns amber ≤21 days and red ≤7 days (hidden once Applied = Yes).
B28: Action Required | E28: =COUNTIF(Tracker!$F$5:$F$104,B28) -> 1 | F28: =COUNTIFS(Tracker!$F$5:$F$104,B28,Tracker!$J$5:$J$104,"Yes") -> 1 | H28: ▸ Add new employers in the next empty Tracker row (formatting runs to row 104).
B29: Restricted | E29: =COUNTIF(Tracker!$F$5:$F$104,B29) -> 2 | F29: =COUNTIFS(Tracker!$F$5:$F$104,B29,Tracker!$J$5:$J$104,"Yes") -> 0 | H29: ▸ Edit dropdown options any time on the Lists sheet.
B30: No Sponsorship | E30: =COUNTIF(Tracker!$F$5:$F$104,B30) -> 1 | F30: =COUNTIFS(Tracker!$F$5:$F$104,B30,Tracker!$J$5:$J$104,"Yes") -> 0
B31: Unconfirmed | E31: =COUNTIF(Tracker!$F$5:$F$104,B31) -> 1 | F31: =COUNTIFS(Tracker!$F$5:$F$104,B31,Tracker!$J$5:$J$104,"Yes") -> 0
B32: N/A | E32: =COUNTIF(Tracker!$F$5:$F$104,B32) -> 1 | F32: =COUNTIFS(Tracker!$F$5:$F$104,B32,Tracker!$J$5:$J$104,"Yes") -> 0
B34: Sponsorship data: UK Employer Tracker, 12 Oct 2026. Always confirm sponsor status on the UK Government Register of Licensed Sponsors (Workers) and salary thresholds before applying. Priority levels are suggested defaults and editable.

Sheet Tracker
B1: UK EMPLOYER APPLICATION TRACKER
B2: IT Audit · Technology Risk · Data & Analytics | Skilled Worker sponsorship pipeline | Baseline: 12 Oct 2026
A3: OPPORTUNITY | J3: APPLICATION | M3: ONLINE ASSESSMENT | O3: INTERVIEW | Q3: ASSESSMENT CENTRE | S3: OFFER | U3: NOTES
A4: # | B4: Employer | C4: Sector | D4: Role / Opportunity | E4: Location | F4: Sponsorship | G4: Priority | H4: Deadline | I4: Days Left | J4: Applied? | K4: Date Applied | L4: Application Status | M4: Status | N4: Date | O4: Status | P4: Date | Q4: Status | R4: Date | S4: Offer | T4: Offer Date | U4: Next Action | V4: Notes / Sponsorship Detail
A5: =IF(B5="","",ROW()-4) -> 1 | B5: CIL Strategy Consultants | C5: Consulting | D5: Data, Analytics & AI Analyst | E5: London / Frome | F5: Check per role | G5: High | H5: 46311 | I5: =IF(OR(H5="",J5="Yes"),"",H5-TODAY()) -> 2 | J5: No | L5: Not Applied | M5: Not Invited | O5: Not Invited | Q5: Not Invited | S5: No Offer Yet | U5: Submit early; verify right-to-work requirements | V5: Sponsorship varies by entry path
A6: =IF(B6="","",ROW()-4) -> 2 | B6: CIL Strategy Consultants | C6: Consulting | D6: Strategy Analyst | E6: London / Frome | F6: Check per role | G6: High | H6: 46318 | I6: =IF(OR(H6="",J6="Yes"),"",H6-TODAY()) -> 9 | J6: No | L6: Not Applied | M6: Not Invited | O6: Not Invited | Q6: Not Invited | S6: No Offer Yet | U6: Submit application form and CV | V6: Sponsorship varies by entry path
A7: =IF(B7="","",ROW()-4) -> 3 | B7: BlackRock | C7: Finance | D7: Full-Time Analyst 2027 | E7: London / Edinburgh | F7: High Potential | G7: High | H7: 46325 | I7: =IF(OR(H7="",J7="Yes"),"",H7-TODAY()) -> 16 | J7: No | L7: Not Applied | M7: Not Invited | O7: Not Invited | Q7: Not Invited | S7: No Offer Yet | U7: Prioritise quantitative / analytical tracks | V7: Actively sponsors qualified graduate analysts
A8: =IF(B8="","",ROW()-4) -> 4 | B8: Capgemini | C8: Consulting | D8: Project Management & Operations Analyst (2027) | E8: Telford / London / Manchester | F8: Check per role | G8: Medium | I8: =IF(OR(H8="",J8="Yes"),"",H8-TODAY()) | J8: No | L8: Not Applied | M8: Not Invited | O8: Not Invited | Q8: Not Invited | S8: No Offer Yet | U8: Apply promptly before pool closes | V8: Rolling (Oct 2026). Core Tech/AI roles frequently eligible
A9: =IF(B9="","",ROW()-4) -> 5 | B9: PwC | C9: Consulting | D9: Graduate Technology & AI / Risk Assurance | E9: Birmingham / London / Manchester | F9: High Potential | G9: High | I9: =IF(OR(H9="",J9="Yes"),"",H9-TODAY()) | J9: No | L9: Not Applied | M9: Not Invited | O9: Not Invited | Q9: Not Invited | S9: No Offer Yet | U9: High priority for IT Audit / Tech Risk skills | V9: Rolling. Broad Skilled Worker sponsor for tech schemes
A10: =IF(B10="","",ROW()-4) -> 6 | B10: Rolls-Royce | C10: Engineering | D10: Engineering & Tech Graduate | E10: Derby / Bristol / Solihull | F10: Action Required | G10: Medium | I10: =IF(OR(H10="",J10="Yes"),"",H10-TODAY()) | J10: Yes | L10: Submitted | M10: Not Invited | O10: Not Invited | Q10: Not Invited | S10: No Offer Yet | U10: Monitor application portal for assessment updates | V10: £31k + £2k bonus. Strict salary threshold & visa checks needed
A11: =IF(B11="","",ROW()-4) -> 7 | B11: Mott MacDonald | C11: Engineering | D11: Graduate Management Consultancy Path (2027) | E11: Birmingham / London / Manchester | F11: No Sponsorship | G11: Low | H11: 46311 | I11: =IF(OR(H11="",J11="Yes"),"",H11-TODAY()) -> 2 | J11: No | L11: Not Applied | M11: Not Invited | O11: Not Invited | Q11: Not Invited | S11: No Offer Yet | U11: Skip — no Skilled Worker sponsorship for 2027 | V11: Explicitly not sponsoring Skilled Worker route for 2027
A12: =IF(B12="","",ROW()-4) -> 8 | B12: PA Consulting | C12: Consulting | D12: Graduate Consulting, Digital & Data | E12: London / Cambridge / Bristol | F12: Check per role | G12: Medium | I12: =IF(OR(H12="",J12="Yes"),"",H12-TODAY()) | J12: No | L12: Not Applied | M12: Not Invited | O12: Not Invited | Q12: Not Invited | S12: No Offer Yet | U12: Check careers portal for open dates | V12: Selective sponsorship for tech/analytics
A13: =IF(B13="","",ROW()-4) -> 9 | B13: Kearney | C13: Consulting | D13: Business Analyst & Digital Consulting | E13: London | F13: Check per role | G13: Low | I13: =IF(OR(H13="",J13="Yes"),"",H13-TODAY()) | J13: No | L13: Not Applied | M13: Not Invited | O13: Not Invited | Q13: Not Invited | S13: No Offer Yet | U13: Check careers portal for open dates | V13: Sponsors competitive business analyst routes
A14: =IF(B14="","",ROW()-4) -> 10 | B14: BDO | C14: Consulting | D14: Tech Risk, Advisory & Data Analytics | E14: London & Regional | F14: Check per role | G14: Medium | I14: =IF(OR(H14="",J14="Yes"),"",H14-TODAY()) | J14: No | L14: Not Applied | M14: Not Invited | O14: Not Invited | Q14: Not Invited | S14: No Offer Yet | U14: Check early careers portal | V14: Tech Risk & Cyber often sponsor
A15: =IF(B15="","",ROW()-4) -> 11 | B15: KPMG | C15: Consulting | D15: Tech Consulting, IT Audit & Experienced Hire | E15: London & Regional | F15: High Potential | G15: High | I15: =IF(OR(H15="",J15="Yes"),"",H15-TODAY()) | J15: No | L15: Not Applied | M15: Not Invited | O15: Not Invited | Q15: Not Invited | S15: No Offer Yet | U15: Explore internal transfer / experienced hire route | V15: Licensed sponsor; sponsors skilled tech/audit roles
A16: =IF(B16="","",ROW()-4) -> 12 | B16: Deloitte | C16: Consulting | D16: Technology & Data Analytics Graduate Scheme | E16: London & Regional | F16: High Potential | G16: Medium | I16: =IF(OR(H16="",J16="Yes"),"",H16-TODAY()) | J16: No | L16: Not Applied | M16: Not Invited | O16: Not Invited | Q16: Not Invited | S16: No Offer Yet | U16: Check scheme opening dates | V16: Extensive UK sponsor licence
A17: =IF(B17="","",ROW()-4) -> 13 | B17: McKinsey & Co. | C17: Consulting | D17: Business Analyst, Digital & Data Engineering | E17: London | F17: High Potential | G17: Medium | I17: =IF(OR(H17="",J17="Yes"),"",H17-TODAY()) | J17: No | L17: Not Applied | M17: Not Invited | O17: Not Invited | Q17: Not Invited | S17: No Offer Yet | U17: Check application window | V17: Active sponsor across analyst tiers
A18: =IF(B18="","",ROW()-4) -> 14 | B18: Brevan Howard | C18: Finance | D18: Quant, Tech Assurance & Analytics Roles | E18: London | F18: Selective | G18: Low | I18: =IF(OR(H18="",J18="Yes"),"",H18-TODAY()) | J18: No | L18: Not Applied | M18: Not Invited | O18: Not Invited | Q18: Not Invited | S18: No Offer Yet | U18: Review tech assurance openings | V18: High-skill technical/quantitative roles
A19: =IF(B19="","",ROW()-4) -> 15 | B19: Wellington Management | C19: Finance | D19: Investment Research & Tech Analyst | E19: London | F19: Check per role | G19: Low | I19: =IF(OR(H19="",J19="Yes"),"",H19-TODAY()) | J19: No | L19: Not Applied | M19: Not Invited | O19: Not Invited | Q19: Not Invited | S19: No Offer Yet | U19: Check careers portal | V19: Tier 2 / Skilled Worker licence held
A20: =IF(B20="","",ROW()-4) -> 16 | B20: Antin Infrastructure | C20: Finance | D20: Investment & Portfolio Analytics | E20: London | F20: Selective | G20: Low | I20: =IF(OR(H20="",J20="Yes"),"",H20-TODAY()) | J20: No | L20: Not Applied | M20: Not Invited | O20: Not Invited | Q20: Not Invited | S20: No Offer Yet | U20: Verify salary thresholds | V20: Specialist sponsor
A21: =IF(B21="","",ROW()-4) -> 17 | B21: J.P. Morgan | C21: Finance | D21: Tech Analyst Programme & Risk Engineering | E21: London / Bournemouth / Glasgow | F21: High Potential | G21: Medium | I21: =IF(OR(H21="",J21="Yes"),"",H21-TODAY()) | J21: No | L21: Not Applied | M21: Not Invited | O21: Not Invited | Q21: Not Invited | S21: No Offer Yet | U21: Check programme dates | V21: Robust global mobility and visa sponsorship
A22: =IF(B22="","",ROW()-4) -> 18 | B22: Standard Chartered | C22: Finance | D22: Tech & Data Analyst Schemes, Audit | E22: London | F22: High Potential | G22: Medium | I22: =IF(OR(H22="",J22="Yes"),"",H22-TODAY()) | J22: No | L22: Not Applied | M22: Not Invited | O22: Not Invited | Q22: Not Invited | S22: No Offer Yet | U22: Check programme dates | V22: Frequent sponsor for international talent
A23: =IF(B23="","",ROW()-4) -> 19 | B23: LSEG | C23: Finance | D23: Data, Technology & Risk Analyst Schemes | E23: London & Regional | F23: High Potential | G23: Medium | I23: =IF(OR(H23="",J23="Yes"),"",H23-TODAY()) | J23: No | L23: Not Applied | M23: Not Invited | O23: Not Invited | Q23: Not Invited | S23: No Offer Yet | U23: Check programme dates | V23: Major sponsor for financial data/tech
... A26: =IF(B26="","",ROW()-4) -> 22 | B26: Shell | C26: Energy | D26: Data, Engineering & Commercial Tech | E26: London & Regional | F26: High Potential | G26: Medium | I26: =IF(OR(H26="",J26="Yes"),"",H26-TODAY()) | J26: No | L26: Not Applied | M26: Not Invited | O26: Not Invited | Q26: Not Invited | S26: No Offer Yet | U26: Check careers portal | V26: Licensed sponsor across STEM roles
A27: =IF(B27="","",ROW()-4) -> 23 | B27: Chevron | C27: Energy | D27: Digital Transformation & Tech Analysts | E27: London & Operations | F27: Selective | G27: Low | I27: =IF(OR(H27="",J27="Yes"),"",H27-TODAY()) | J27: No | L27: Not Applied | M27: Not Invited | O27: Not Invited | Q27: Not Invited | S27: No Offer Yet | U27: Check individual vacancy criteria
A28: =IF(B28="","",ROW()-4) -> 24 | B28: Tesco | C28: Retail & Tech | D28: Tech, Data & Business Analytics | E28: Welwyn Garden City / London | F28: Check per role | G28: Low | I28: =IF(OR(H28="",J28="Yes"),"",H28-TODAY()) | J28: No | L28: Not Applied | M28: Not Invited | O28: Not Invited | Q28: Not Invited | S28: No Offer Yet | U28: Check careers portal | V28: Sponsors skilled technology roles
A29: =IF(B29="","",ROW()-4) -> 25 | B29: Morrisons | C29: Retail & Tech | D29: Head Office Data Analytics & IT | E29: Bradford & HQ | F29: Restricted | G29: Low | I29: =IF(OR(H29="",J29="Yes"),"",H29-TODAY()) | J29: No | L29: Not Applied | M29: Not Invited | O29: Not Invited | Q29: Not Invited | S29: No Offer Yet | U29: Low priority | V29: Rarely sponsors entry-level schemes
A30: =IF(B30="","",ROW()-4) -> 26 | B30: Huawei UK | C30: Retail & Tech | D30: Network, AI & Software Engineering | E30: Reading / London | F30: High Potential | G30: Medium | I30: =IF(OR(H30="",J30="Yes"),"",H30-TODAY()) | J30: No | L30: Not Applied | M30: Not Invited | O30: Not Invited | Q30: Not Invited | S30: No Offer Yet | U30: Check careers portal | V30: Actively sponsors technical hires
A31: =IF(B31="","",ROW()-4) -> 27 | B31: NHBC | C31: Retail & Tech | D31: Operational Resilience & IT Risk | E31: Milton Keynes | F31: Check per role | G31: Low | I31: =IF(OR(H31="",J31="Yes"),"",H31-TODAY()) | J31: No | L31: Not Applied | M31: Not Invited | O31: Not Invited | Q31: Not Invited | S31: No Offer Yet | U31: Check salary compliance | V31: Requires Skilled Worker salary compliance
A32: =IF(B32="","",ROW()-4) -> 28 | B32: NHS (Digital/X) | C32: Public Sector | D32: Health Data Science, IT Audit & Tech | E32: Nationwide | F32: Role Dependent | G32: Low | I32: =IF(OR(H32="",J32="Yes"),"",H32-TODAY()) | J32: No | L32: Not Applied | M32: Not Invited | O32: Not Invited | Q32: Not Invited | S32: No Offer Yet | U32: Check NHS Jobs for Band/salary fit | V32: Sponsors if role meets Band/Salary criteria
A33: =IF(B33="","",ROW()-4) -> 29 | B33: NLNG | C33: Energy | D33: Graduate & Mid-Level Engineering/IT | E33: Nigeria | F33: N/A | G33: Low | I33: =IF(OR(H33="",J33="Yes"),"",H33-TODAY()) | J33: No | L33: Not Applied | M33: Not Invited | O33: Not Invited | Q33: Not Invited | S33: No Offer Yet | U33: Domestic Nigerian hiring | V33: Not a UK visa route
A34: =IF(B34="","",ROW()-4) -> 30 | B34: Renaissance | C34: Finance | D34: Specific entity ID required | E34: Various UK | F34: Unconfirmed | G34: Low | I34: =IF(OR(H34="",J34="Yes"),"",H34-TODAY()) | J34: No | L34: Not Applied | M34: Not Invited | O34: Not Invited | Q34: Not Invited | S34: No Offer Yet | U34: Confirm exact business entity name | V34: Unconfirmed
A35: =IF(B35="","",ROW()-4) | I35: =IF(OR(H35="",J35="Yes"),"",H35-TODAY())
A36: =IF(B36="","",ROW()-4) | I36: =IF(OR(H36="",J36="Yes"),"",H36-TODAY())
A37: =IF(B37="","",ROW()-4) | I37: =IF(OR(H37="",J37="Yes"),"",H37-TODAY())
A38: =IF(B38="","",ROW()-4) | I38: =IF(OR(H38="",J38="Yes"),"",H38-TODAY())
A39: =IF(B39="","",ROW()-4) | I39: =IF(OR(H39="",J39="Yes"),"",H39-TODAY())
A40: =IF(B40="","",ROW()-4) | I40: =IF(OR(H40="",J40="Yes"),"",H40-TODAY())
A41: =IF(B41="","",ROW()-4) | I41: =IF(OR(H41="",J41="Yes"),"",H41-TODAY())
A42: =IF(B42="","",ROW()-4) | I42: =IF(OR(H42="",J42="Yes"),"",H42-TODAY())
...

Sheet Lists
A1: Dropdown source lists — edit the values below to change the dropdown options in the Tracker.
A3: Sponsorship | B3: Priority | C3: Yes/No | D3: Application Status | E3: Stage Status | F3: Offer
A4: High Potential | B4: High | C4: Yes | D4: Not Applied | E4: Not Invited | F4: No Offer Yet
A5: Check per role | B5: Medium | C5: No | D5: In Progress | E5: Invited | F5: Offer Received
A6: Selective | B6: Low | D6: Submitted | E6: Scheduled | F6: Accepted
A7: Role Dependent | D7: Under Review | E7: Completed | F7: Declined
A8: Action Required | D8: Rejected | E8: Passed | F8: Rejected
A9: Restricted | D9: Withdrawn | E9: Failed
A10: No Sponsorship | D10: Offer Received
A11: Unconfirmed
A12: N/A
